Workbook
Name _smrik_Assets_1: Assets!$A$1
Name _smrik_Assets_10: Assets!$A$10
Name _smrik_Assets_11: Assets!$A$11
Name _smrik_Assets_12: Assets!$A$12
Name _smrik_Assets_13: Assets!$A$13
Name _smrik_Assets_14: Assets!$A$14
Name _smrik_Assets_15: Assets!$A$15
Name _smrik_Assets_16: Assets!$A$16
Name _smrik_Assets_17: Assets!$A$17
Name _smrik_Assets_18: Assets!$A$18
Name _smrik_Assets_19: Assets!$A$19
Name _smrik_Assets_2: Assets!$A$2
Name _smrik_Assets_20: Assets!$A$20
Name _smrik_Assets_21: Assets!$A$21
Name _smrik_Assets_22: Assets!$A$22
Name _smrik_Assets_23: Assets!$A$23
Name _smrik_Assets_24: Assets!$A$24
Name _smrik_Assets_3: Assets!$A$3
Name _smrik_Assets_4: Assets!$A$4
Name _smrik_Assets_5: Assets!$A$5
Name _smrik_Assets_6: Assets!$A$6
Name _smrik_Assets_7: Assets!$A$7
Name _smrik_Assets_8: Assets!$A$8
Name _smrik_Assets_9: Assets!$A$9
Name _smrik_BalanceSheet_1: BalanceSheet!$A$1
Name _smrik_BalanceSheet_10: BalanceSheet!$A$10
Name _smrik_BalanceSheet_11: BalanceSheet!$A$11
Name _smrik_BalanceSheet_12: BalanceSheet!$A$12
Name _smrik_BalanceSheet_13: BalanceSheet!$A$13
Name _smrik_BalanceSheet_14: BalanceSheet!$A$14
Name _smrik_BalanceSheet_15: BalanceSheet!$A$15
Name _smrik_BalanceSheet_16: BalanceSheet!$A$16
Name _smrik_BalanceSheet_17: BalanceSheet!$A$17
Name _smrik_BalanceSheet_18: BalanceSheet!$A$18
Name _smrik_BalanceSheet_19: BalanceSheet!$A$19
Name _smrik_BalanceSheet_2: BalanceSheet!$A$2
Name _smrik_BalanceSheet_20: BalanceSheet!$A$20
Name _smrik_BalanceSheet_21: BalanceSheet!$A$21
Name _smrik_BalanceSheet_22: BalanceSheet!$A$22
Name _smrik_BalanceSheet_23: BalanceSheet!$A$23
Name _smrik_BalanceSheet_24: BalanceSheet!$A$24
Name _smrik_BalanceSheet_25: BalanceSheet!$A$25
Name _smrik_BalanceSheet_26: BalanceSheet!$A$26
Name _smrik_BalanceSheet_27: BalanceSheet!$A$27
Name _smrik_BalanceSheet_28: BalanceSheet!$A$28
Name _smrik_BalanceSheet_29: BalanceSheet!$A$29
Name _smrik_BalanceSheet_3: BalanceSheet!$A$3
Name _smrik_BalanceSheet_30: BalanceSheet!$A$30
Name _smrik_BalanceSheet_31: BalanceSheet!$A$31
Name _smrik_BalanceSheet_32: BalanceSheet!$A$32
Name _smrik_BalanceSheet_33: BalanceSheet!$A$33
Name _smrik_BalanceSheet_34: BalanceSheet!$A$34
Name _smrik_BalanceSheet_35: BalanceSheet!$A$35
Name _smrik_BalanceSheet_36: BalanceSheet!$A$36
Name _smrik_BalanceSheet_37: BalanceSheet!$A$37
Name _smrik_BalanceSheet_38: BalanceSheet!$A$38
Name _smrik_BalanceSheet_4: BalanceSheet!$A$4
Name _smrik_BalanceSheet_5: BalanceSheet!$A$5
Name _smrik_BalanceSheet_6: BalanceSheet!$A$6
Name _smrik_BalanceSheet_7: BalanceSheet!$A$7

Sheet Review
A1: BATH & BODY WORKS, INC. | E2E development model
A2: Measurement 2026-08-01; information cutoff 2026-09-16. All financial assumptions provisional.
A3: Metric | B3: Value | D3: Open Income
A4: Value per share | B4: =DCF!B19 -> 39.864567 | D4: Open BalanceSheet
A5: WACC | B5: =DCF!B6 -> 0.083680306 | D5: Open CashFlow
A6: Calculation integrity | B6: =Checks!B9 -> PASS | D6: Open History
A7: Decision readiness | B7: Screen-grade: provisional assumptions; financial review pending | D7: Open DCF
A8: Human financial approval | B8: FALSE | D8: Open Sensitivity
A9: Reviewer rationale | B9: Independent review pending
A10: Analyst rationale | B10: Free weekend research baseline for BBWI. Quote 16.73 USD captured 2026-09-16T21:00:44.977490+00:00; constant revenue growth -2%, beta 1.4, risk-free 4%, ERP 5.5%, debt rate 6.5%, terminal growth 2% are explicit scenario choices, not observed market estimates. No runtime paid analyst. Review earnings normalization separately before relying on the DCF.
A11: Caveat 1 | B11: Consolidated development scenario: no segment forecast. Revenue growth controls the whole company; additional revenue slots are structural zeros, not missing source facts.
A12: Caveat 2 | B12: Each FY/YTD reconciles to reported EBIT. Expense magnitudes are presentation conversions; signed facts remain in History/Evidence. Absent categories are not asserted to be zero. Forecast ratios start at TTM and include embedded D&A/SBC; total D&A is replaced once below EBITDA. No allocation of D&A between COGS and SG&A is claimed.
A13: Caveat 3 | B13: Current operating assets/liabilities are explicit reported parent-minus-component groups and scale with revenue; tax accruals, leases and deferred revenue remain aggregated. No balance plugs.
A14: Caveat 4 | B14: Only separately presented borrowing and investment amounts are isolated; components embedded in other balances remain there. Debt uses carrying values and constant refinancing; investments use carrying-value and scenario-yield proxies.
A15: Caveat 5 | B15: Total historical D&A is provisionally assigned to disclosed PPE/finite-intangible pools by carrying weights; forecast uses declining balance with half-period additions. Hidden intangible detail remains in other balances; no claim of sourced depreciation lives.
A16: Caveat 6 | B16: Reported productive-asset capex, when combined, is allocated to the PP&E schedule provisionally; PP&E may include finance-lease ROU assets. Depreciation-only disclosures are not relabeled as separately sourced total amortization. Financed asset additions are not projected separately.
A17: Caveat 7 | B17: Goodwill and other noncurrent balances are held flat. No future acquisitions or intangible additions by default; omitted additions may be a material scenario limitation.
A18: Caveat 8 | B18: Where note detail is available, finance leases are reclassified into refinanced debt and nonmarketable investment components into the carrying-value bridge. Operating leases remain operating. Future asset additions are cash funded; no new finance leases are assumed.
A19: Caveat 9 | B19: Default distributions are zero to retain cash for capital spending; analyst controls may change this. No automatic debt/cash plugs. Cash tax equals book tax; usable historical effective-tax ratio retained, otherwise explicit 25% normalized development tax rate (no NOL modeling). Future SBC remains expensed in UFCF, with a separate cash addback and equity contribution.
A20: Caveat 10 | B20: Diluted weighted-average shares, or net income divided by rounded consolidated diluted EPS when the count is not on the face statement, are a valuation proxy; no separate award claim. Market-price, beta, yields and terminal growth are provisional scenarios, not observed investment inputs.
... A26: Local edits | B26: Editable inputs invalidate attached review; arbitrary formula changes are not certified. Rebuild through CLI for a new reviewed version.

Sheet Income
A1: BBWI — Income
A2: USD millions. Actuals | TTM / latest balances | annual forecasts. Blank = unavailable or not comparable.
A3: Line | B3: FY2021A 2022-01-29 | C3: FY2022A 2023-01-28 | D3: FY2023A 2024-02-03 | E3: FY2024A 2025-02-01 | F3: FY2025A 2026-01-31 | G3: TTM 2026-08-01 | H3: FY2027E 2028-01-29 | I3: FY2028E 2029-01-27 | J3: FY2029E 2030-01-26 | K3: FY2030E 2031-01-25 | L3: FY2031E 2032-01-24 | M3: FY2032E 2033-01-22 | N3: FY2033E 2034-01-21 | O3: FY2034E 2035-01-20 | P3: FY2035E 2036-01-19 | Q3: FY2036E 2037-01-17
A5: Period fraction (364-day fiscal basis) | H5: =1 -> 1 | I5: =1 -> 1 | J5: =1 -> 1 | K5: =1 -> 1 | L5: =1 -> 1 | M5: =1 -> 1 | N5: =1 -> 1 | O5: =1 -> 1 | ... Q5: =1 -> 1
A8: Revenue | B8: =IF(ISNUMBER(History!B7),History!B7,"") -> 7882 | C8: =IF(ISNUMBER(History!C7),History!C7,"") -> 7560 | D8: =IF(ISNUMBER(History!D7),History!D7,"") -> 7429 | E8: =IF(ISNUMBER(History!E7),History!E7,"") -> 7307 | F8: =IF(ISNUMBER(History!F7),History!F7,"") -> 7291 | G8: =IF(ISNUMBER(History!G7),History!G7,"") -> 7209 | H8: =(Inputs!$B$45+Stub!B6)*(1+H9) -> 6980.2068 | I8: =H8*(1+I9) -> 6840.6027 | J8: =I8*(1+J9) -> 6703.7906 | K8: =J8*(1+K9) -> 6569.7148 | L8: =K8*(1+L9) -> 6438.3205 | M8: =L8*(1+M9) -> 6309.5541 | N8: =M8*(1+N9) -> 6183.363 | O8: =N8*(1+O9) -> 6059.6958 | P8: =O8*(1+P9) -> 5938.5018 | Q8: =P8*(1+Q9) -> 5819.7318
A9: Revenue growth | C9: =IF(AND(COUNT(C8,B8)=2,B8<>0),C8/B8-1,"") -> -0.040852575 | D9: =IF(AND(COUNT(D8,C8)=2,C8<>0),D8/C8-1,"") -> -0.017328042 | E9: =IF(AND(COUNT(E8,D8)=2,D8<>0),E8/D8-1,"") -> -0.016422129 | F9: =IF(AND(COUNT(F8,E8)=2,E8<>0),F8/E8-1,"") -> -0.0021896811 | H9: =Inputs!$B$54 -> -0.02 | I9: =Inputs!$B$54 -> -0.02 | J9: =Inputs!$B$54 -> -0.02 | K9: =Inputs!$B$54 -> -0.02 | L9: =Inputs!$B$54 -> -0.02 | M9: =Inputs!$B$54 -> -0.02 | N9: =Inputs!$B$54 -> -0.02 | O9: =Inputs!$B$54 -> -0.02 | ... Q9: =Inputs!$B$54 -> -0.02
A11: Cost of revenue | B11: =IF(ISNUMBER(History!B39),History!B39,"") -> 4027 | C11: =IF(ISNUMBER(History!C39),History!C39,"") -> 4305 | D11: =IF(ISNUMBER(History!D39),History!D39,"") -> 4193 | E11: =IF(ISNUMBER(History!E39),History!E39,"") -> 4073 | F11: =IF(ISNUMBER(History!F39),History!F39,"") -> 4102 | G11: =IF(ISNUMBER(History!G39),History!G39,"") -> 4028 | H11: =H8*H12 -> 3900.1627 | I11: =I8*I12 -> 3822.1595 | J11: =J8*J12 -> 3745.7163 | K11: =K8*K12 -> 3670.8019 | L11: =L8*L12 -> 3597.3859 | M11: =M8*M12 -> 3525.4382 | N11: =N8*N12 -> 3454.9294 | O11: =O8*O12 -> 3385.8308 | ... Q11: =Q8*Q12 -> 3251.7519
A12: Cost of revenue / revenue | B12: =IF(AND(COUNT(B11,B8)=2,B8<>0),B11/B8,"") -> 0.51091094 | C12: =IF(AND(COUNT(C11,C8)=2,C8<>0),C11/C8,"") -> 0.56944444 | D12: =IF(AND(COUNT(D11,D8)=2,D8<>0),D11/D8,"") -> 0.56440975 | E12: =IF(AND(COUNT(E11,E8)=2,E8<>0),E11/E8,"") -> 0.5574107 | F12: =IF(AND(COUNT(F11,F8)=2,F8<>0),F11/F8,"") -> 0.56261144 | G12: =IF(AND(COUNT(G11,G8)=2,G8<>0),G11/G8,"") -> 0.55874601 | H12: =Inputs!$B$66 -> 0.55874601 | I12: =Inputs!$B$66 -> 0.55874601 | J12: =Inputs!$B$66 -> 0.55874601 | K12: =Inputs!$B$66 -> 0.55874601 | L12: =Inputs!$B$66 -> 0.55874601 | M12: =Inputs!$B$66 -> 0.55874601 | N12: =Inputs!$B$66 -> 0.55874601 | O12: =Inputs!$B$66 -> 0.55874601 | ... Q12: =Inputs!$B$66 -> 0.55874601
A14: Gross profit before D&A replacement | B14: =IF(COUNT(B8,B11)=2,B8-B11,"") -> 3855 | C14: =IF(COUNT(C8,C11)=2,C8-C11,"") -> 3255 | D14: =IF(COUNT(D8,D11)=2,D8-D11,"") -> 3236 | E14: =IF(COUNT(E8,E11)=2,E8-E11,"") -> 3234 | F14: =IF(COUNT(F8,F11)=2,F8-F11,"") -> 3189 | G14: =IF(COUNT(G8,G11)=2,G8-G11,"") -> 3181 | H14: =IF(COUNT(H8,H11)=2,H8-H11,"") -> 3080.0441 | I14: =IF(COUNT(I8,I11)=2,I8-I11,"") -> 3018.4432 | ... Q14: =IF(COUNT(Q8,Q11)=2,Q8-Q11,"") -> 2567.9799
A15: Gross margin before D&A replacement | B15: =IF(AND(COUNT(B14,B8)=2,B8<>0),B14/B8,"") -> 0.48908906 | C15: =IF(AND(COUNT(C14,C8)=2,C8<>0),C14/C8,"") -> 0.43055556 | D15: =IF(AND(COUNT(D14,D8)=2,D8<>0),D14/D8,"") -> 0.43559025 | E15: =IF(AND(COUNT(E14,E8)=2,E8<>0),E14/E8,"") -> 0.4425893 | F15: =IF(AND(COUNT(F14,F8)=2,F8<>0),F14/F8,"") -> 0.43738856 | G15: =IF(AND(COUNT(G14,G8)=2,G8<>0),G14/G8,"") -> 0.44125399 | H15: =IF(AND(COUNT(H14,H8)=2,H8<>0),H14/H8,"") -> 0.44125399 | I15: =IF(AND(COUNT(I14,I8)=2,I8<>0),I14/I8,"") -> 0.44125399 | ... Q15: =IF(AND(COUNT(Q14,Q8)=2,Q8<>0),Q14/Q8,"") -> 0.44125399
A17: SG&A | B17: =IF(ISNUMBER(History!B40),History!B40,"") -> 1846 | C17: =IF(ISNUMBER(History!C40),History!C40,"") -> 1879 | D17: =IF(ISNUMBER(History!D40),History!D40,"") -> 1951 | E17: =IF(ISNUMBER(History!E40),History!E40,"") -> 1968 | F17: =IF(ISNUMBER(History!F40),History!F40,"") -> 2063 | G17: =IF(ISNUMBER(History!G40),History!G40,"") -> 1975 | H17: =H8*H18 -> 1912.3191 | I17: =I8*I18 -> 1874.0727 | J17: =J8*J18 -> 1836.5913 | K17: =K8*K18 -> 1799.8594 | L17: =L8*L18 -> 1763.8623 | M17: =M8*M18 -> 1728.585 | N17: =N8*N18 -> 1694.0133 | O17: =O8*O18 -> 1660.133 | ... Q17: =Q8*Q18 -> 1594.3918
A18: SG&A / revenue | B18: =IF(AND(COUNT(B17,B8)=2,B8<>0),B17/B8,"") -> 0.23420452 | C18: =IF(AND(COUNT(C17,C8)=2,C8<>0),C17/C8,"") -> 0.24854497 | D18: =IF(AND(COUNT(D17,D8)=2,D8<>0),D17/D8,"") -> 0.26261946 | E18: =IF(AND(COUNT(E17,E8)=2,E8<>0),E17/E8,"") -> 0.26933078 | F18: =IF(AND(COUNT(F17,F8)=2,F8<>0),F17/F8,"") -> 0.28295158 | G18: =IF(AND(COUNT(G17,G8)=2,G8<>0),G17/G8,"") -> 0.2739631 | H18: =Inputs!$B$67 -> 0.2739631 | I18: =Inputs!$B$67 -> 0.2739631 | J18: =Inputs!$B$67 -> 0.2739631 | K18: =Inputs!$B$67 -> 0.2739631 | L18: =Inputs!$B$67 -> 0.2739631 | M18: =Inputs!$B$67 -> 0.2739631 | N18: =Inputs!$B$67 -> 0.2739631 | O18: =Inputs!$B$67 -> 0.2739631 | ... Q18: =Inputs!$B$67 -> 0.2739631
A20: R&D | B20: =IF(ISNUMBER(History!B41),History!B41,"") | C20: =IF(ISNUMBER(History!C41),History!C41,"") | D20: =IF(ISNUMBER(History!D41),History!D41,"") | E20: =IF(ISNUMBER(History!E41),History!E41,"") | F20: =IF(ISNUMBER(History!F41),History!F41,"") | G20: =IF(ISNUMBER(History!G41),History!G41,"")
A21: R&D / revenue | B21: =IF(AND(COUNT(B20,B8)=2,B8<>0),B20/B8,"") | C21: =IF(AND(COUNT(C20,C8)=2,C8<>0),C20/C8,"") | D21: =IF(AND(COUNT(D20,D8)=2,D8<>0),D20/D8,"") | E21: =IF(AND(COUNT(E20,E8)=2,E8<>0),E20/E8,"") | F21: =IF(AND(COUNT(F20,F8)=2,F8<>0),F20/F8,"") | G21: =IF(AND(COUNT(G20,G8)=2,G8<>0),G20/G8,"") | H21: =IF(AND(COUNT(H20,H8)=2,H8<>0),H20/H8,"") | I21: =IF(AND(COUNT(I20,I8)=2,I8<>0),I20/I8,"") | ... Q21: =IF(AND(COUNT(Q20,Q8)=2,Q8<>0),Q20/Q8,"")
A26: Total costs before D&A replacement | B26: =IF(ISNUMBER(History!B50),History!B50,"") -> 5873 | C26: =IF(ISNUMBER(History!C50),History!C50,"") -> 6184 | D26: =IF(ISNUMBER(History!D50),History!D50,"") -> 6144 | E26: =IF(ISNUMBER(History!E50),History!E50,"") -> 6041 | F26: =IF(ISNUMBER(History!F50),History!F50,"") -> 6165 | G26: =IF(ISNUMBER(History!G50),History!G50,"") -> 6003 | H26: =H11+H17 -> 5812.4818 | I26: =I11+I17 -> 5696.2322 | J26: =J11+J17 -> 5582.3075 | K26: =K11+K17 -> 5470.6614 | L26: =L11+L17 -> 5361.2482 | M26: =M11+M17 -> 5254.0232 | N26: =N11+N17 -> 5148.9427 | O26: =O11+O17 -> 5045.9639 | ... Q26: =Q11+Q17 -> 4846.1437
A27: Total costs / revenue | B27: =IF(AND(COUNT(B26,B8)=2,B8<>0),B26/B8,"") -> 0.74511545 | C27: =IF(AND(COUNT(C26,C8)=2,C8<>0),C26/C8,"") -> 0.81798942 | D27: =IF(AND(COUNT(D26,D8)=2,D8<>0),D26/D8,"") -> 0.82702921 | E27: =IF(AND(COUNT(E26,E8)=2,E8<>0),E26/E8,"") -> 0.82674148 | F27: =IF(AND(COUNT(F26,F8)=2,F8<>0),F26/F8,"") -> 0.84556302 | G27: =IF(AND(COUNT(G26,G8)=2,G8<>0),G26/G8,"") -> 0.83270911 | H27: =H26/H8 -> 0.83270911 | I27: =I26/I8 -> 0.83270911 | J27: =J26/J8 -> 0.83270911 | K27: =K26/K8 -> 0.83270911 | L27: =L26/L8 -> 0.83270911 | M27: =M26/M8 -> 0.83270911 | N27: =N26/N8 -> 0.83270911 | O27: =O26/O8 -> 0.83270911 | ... Q27: =Q26/Q8 -> 0.83270911
A29: Estimated embedded D&A removed | H29: =H8*H30 -> 238.19266 | I29: =I8*I30 -> 233.42881 | J29: =J8*J30 -> 228.76023 | K29: =K8*K30 -> 224.18502 | L29: =L8*L30 -> 219.70132 | M29: =M8*M30 -> 215.3073 | N29: =N8*N30 -> 211.00115 | O29: =O8*O30 -> 206.78113 | ... Q29: =Q8*Q30 -> 198.5926
A30: Embedded reported D&A / revenue | H30: =Inputs!$B$31/Inputs!$B$27 -> 0.034124012 | I30: =Inputs!$B$31/Inputs!$B$27 -> 0.034124012 | J30: =Inputs!$B$31/Inputs!$B$27 -> 0.034124012 | K30: =Inputs!$B$31/Inputs!$B$27 -> 0.034124012 | L30: =Inputs!$B$31/Inputs!$B$27 -> 0.034124012 | M30: =Inputs!$B$31/Inputs!$B$27 -> 0.034124012 | N30: =Inputs!$B$31/Inputs!$B$27 -> 0.034124012 | O30: =Inputs!$B$31/Inputs!$B$27 -> 0.034124012 | ... Q30: =Inputs!$B$31/Inputs!$B$27 -> 0.034124012
A32: Additional scenario operating expense | H32: =H8*H33 -> 34.901034 | I32: =I8*I33 -> 34.203013 | J32: =J8*J33 -> 33.518953 | K32: =K8*K33 -> 32.848574 | L32: =L8*L33 -> 32.191603 | M32: =M8*M33 -> 31.54777 | N32: =N8*N33 -> 30.916815 | O32: =O8*O33 -> 30.298479 | ... Q32: =Q8*Q33 -> 29.098659
A33: Additional expense / revenue | H33: 0.005 | I33: 0.005 | J33: 0.005 | K33: 0.005 | L33: 0.005 | M33: 0.005 | N33: 0.005 | O33: 0.005 | P33: 0.005 | Q33: 0.005
A34: EBITDA proxy (EBIT + total D&A) | B34: =IF(COUNT(B40,Assets!B6)=2,B40+Assets!B6,"") -> 2372 | C34: =IF(COUNT(C40,Assets!C6)=2,C40+Assets!C6,"") -> 1597 | D34: =IF(COUNT(D40,Assets!D6)=2,D40+Assets!D6,"") -> 1554 | E34: =IF(COUNT(E40,Assets!E6)=2,E40+Assets!E6,"") -> 1548 | F34: =IF(COUNT(F40,Assets!F6)=2,F40+Assets!F6,"") -> 1380 | G34: =IF(COUNT(G40,Assets!G6)=2,G40+Assets!G6,"") -> 1452 | H34: =H8-H26+H29-H32 -> 1371.0166 | I34: =I8-I26+I29-I32 -> 1343.5963 | J34: =J8-J26+J29-J32 -> 1316.7243 | K34: =K8-K26+K29-K32 -> 1290.3899 | L34: =L8-L26+L29-L32 -> 1264.5821 | M34: =M8-M26+M29-M32 -> 1239.2904 | N34: =N8-N26+N29-N32 -> 1214.5046 | O34: =O8-O26+O29-O32 -> 1190.2145 | ... Q34: =Q8-Q26+Q29-Q32 -> 1143.082
A35: EBITDA margin | B35: =IF(AND(COUNT(B34,B8)=2,B8<>0),B34/B8,"") -> 0.30093885 | C35: =IF(AND(COUNT(C34,C8)=2,C8<>0),C34/C8,"") -> 0.21124339 | D35: =IF(AND(COUNT(D34,D8)=2,D8<>0),D34/D8,"") -> 0.20918024 | E35: =IF(AND(COUNT(E34,E8)=2,E8<>0),E34/E8,"") -> 0.21185165 | F35: =IF(AND(COUNT(F34,F8)=2,F8<>0),F34/F8,"") -> 0.18927445 | G35: =IF(AND(COUNT(G34,G8)=2,G8<>0),G34/G8,"") -> 0.2014149 | H35: =IF(AND(COUNT(H34,H8)=2,H8<>0),H34/H8,"") -> 0.1964149 | I35: =IF(AND(COUNT(I34,I8)=2,I8<>0),I34/I8,"") -> 0.1964149 | ... Q35: =IF(AND(COUNT(Q34,Q8)=2,Q8<>0),Q34/Q8,"") -> 0.1964149
A37: Scheduled PP&E depreciation | H37: =Assets!H13 -> 161.45204 | I37: =Assets!I13 -> 170.26759 | J37: =Assets!J13 -> 177.40125 | K37: =Assets!K13 -> 183.07486 | L37: =Assets!L13 -> 187.4823 | M37: =Assets!M13 -> 190.79297 | N37: =Assets!N13 -> 193.15488 | O37: =Assets!O13 -> 194.69734 | ... Q37: =Assets!Q13 -> 195.76122
A38: Scheduled intangible amortization | H38: =Assets!H21 -> 0 | I38: =Assets!I21 -> 0 | J38: =Assets!J21 -> 0 | K38: =Assets!K21 -> 0 | L38: =Assets!L21 -> 0 | M38: =Assets!M21 -> 0 | N38: =Assets!N21 -> 0 | O38: =Assets!O21 -> 0 | ... Q38: =Assets!Q21 -> 0
A40: EBIT | B40: =IF(ISNUMBER(History!B10),History!B10,"") -> 2009 | C40: =IF(ISNUMBER(History!C10),History!C10,"") -> 1376 | D40: =IF(ISNUMBER(History!D10),History!D10,"") -> 1285 | E40: =IF(ISNUMBER(History!E10),History!E10,"") -> 1266 | F40: =IF(ISNUMBER(History!F10),History!F10,"") -> 1126 | G40: =IF(ISNUMBER(History!G10),History!G10,"") -> 1206 | H40: =H34-H37-H38 -> 1209.5646 | I40: =I34-I37-I38 -> 1173.3287 | J40: =J34-J37-J38 -> 1139.3231 | K40: =K34-K37-K38 -> 1107.315 | L40: =L34-L37-L38 -> 1077.0998 | M40: =M34-M37-M38 -> 1048.4975 | N40: =N34-N37-N38 -> 1021.3497 | O40: =O34-O37-O38 -> 995.51718 | ... Q40: =Q34-Q37-Q38 -> 947.32081
A41: EBIT margin | B41: =IF(AND(COUNT(B40,B8)=2,B8<>0),B40/B8,"") -> 0.25488455 | C41: =IF(AND(COUNT(C40,C8)=2,C8<>0),C40/C8,"") -> 0.18201058 | D41: =IF(AND(COUNT(D40,D8)=2,D8<>0),D40/D8,"") -> 0.17297079 | E41: =IF(AND(COUNT(E40,E8)=2,E8<>0),E40/E8,"") -> 0.17325852 | F41: =IF(AND(COUNT(F40,F8)=2,F8<>0),F40/F8,"") -> 0.15443698 | G41: =IF(AND(COUNT(G40,G8)=2,G8<>0),G40/G8,"") -> 0.16729089 | H41: =IF(AND(COUNT(H40,H8)=2,H8<>0),H40/H8,"") -> 0.17328492 | I41: =IF(AND(COUNT(I40,I8)=2,I8<>0),I40/I8,"") -> 0.17152417 | ... Q41: =IF(AND(COUNT(Q40,Q8)=2,Q8<>0),Q40/Q8,"") -> 0.1627774
A43: Interest expense (actuals: reported sign) | B43: =IF(ISNUMBER(History!B16),History!B16,"") -> -388 | C43: =IF(ISNUMBER(History!C16),History!C16,"") -> -348 | D43: =IF(ISNUMBER(History!D16),History!D16,"") -> -345 | E43: =IF(ISNUMBER(History!E16),History!E16,"") -> -312 | F43: =IF(ISNUMBER(History!F16),History!F16,"") -> -276 | G43: =IF(ISNUMBER(History!G16),History!G16,"") | H43: =(Inputs!$B$18+Inputs!$B$19+Inputs!$B$20)*H44*H5 -> 234.91 | I43: =(Inputs!$B$18+Inputs!$B$19+Inputs!$B$20)*I44*I5 -> 234.91 | J43: =(Inputs!$B$18+Inputs!$B$19+Inputs!$B$20)*J44*J5 -> 234.91 | K43: =(Inputs!$B$18+Inputs!$B$19+Inputs!$B$20)*K44*K5 -> 234.91 | L43: =(Inputs!$B$18+Inputs!$B$19+Inputs!$B$20)*L44*L5 -> 234.91 | M43: =(Inputs!$B$18+Inputs!$B$19+Inputs!$B$20)*M44*M5 -> 234.91 | N43: =(Inputs!$B$18+Inputs!$B$19+Inputs!$B$20)*N44*N5 -> 234.91 | O43: =(Inputs!$B$18+Inputs!$B$19+Inputs!$B$20)*O44*O5 -> 234.91 | ... Q43: =(Inputs!$B$18+Inputs!$B$19+Inputs!$B$20)*Q44*Q5 -> 234.91
A44: Debt interest rate | H44: =Inputs!$B$63 -> 0.065 | I44: =Inputs!$B$63 -> 0.065 | J44: =Inputs!$B$63 -> 0.065 | K44: =Inputs!$B$63 -> 0.065 | L44: =Inputs!$B$63 -> 0.065 | M44: =Inputs!$B$63 -> 0.065 | N44: =Inputs!$B$63 -> 0.065 | O44: =Inputs!$B$63 -> 0.065 | ... Q44: =Inputs!$B$63 -> 0.065
A46: Investment income (scenario risk-free yield) | H46: =(Inputs!$B$5+Inputs!$B$6)*H47*H5 -> 0 | I46: =(Inputs!$B$5+Inputs!$B$6)*I47*I5 -> 0 | J46: =(Inputs!$B$5+Inputs!$B$6)*J47*J5 -> 0 | K46: =(Inputs!$B$5+Inputs!$B$6)*K47*K5 -> 0 | L46: =(Inputs!$B$5+Inputs!$B$6)*L47*L5 -> 0 | M46: =(Inputs!$B$5+Inputs!$B$6)*M47*M5 -> 0 | N46: =(Inputs!$B$5+Inputs!$B$6)*N47*N5 -> 0 | O46: =(Inputs!$B$5+Inputs!$B$6)*O47*O5 -> 0 | ... Q46: =(Inputs!$B$5+Inputs!$B$6)*Q47*Q5 -> 0
A47: Investment yield | H47: =Inputs!$B$60 -> 0.04 | I47: =Inputs!$B$60 -> 0.04 | J47: =Inputs!$B$60 -> 0.04 | K47: =Inputs!$B$60 -> 0.04 | L47: =Inputs!$B$60 -> 0.04 | M47: =Inputs!$B$60 -> 0.04 | N47: =Inputs!$B$60 -> 0.04 | O47: =Inputs!$B$60 -> 0.04 | ... Q47: =Inputs!$B$60 -> 0.04
A49: Pretax income | B49: =IF(ISNUMBER(History!B11),History!B11,"") -> 1423 | C49: =IF(ISNUMBER(History!C11),History!C11,"") -> 1045 | D49: =IF(ISNUMBER(History!D11),History!D11,"") -> 1021 | E49: =IF(ISNUMBER(History!E11),History!E11,"") -> 1028 | F49: =IF(ISNUMBER(History!F11),History!F11,"") -> 882 | G49: =IF(ISNUMBER(History!G11),History!G11,"") -> 971 | H49: =H40-H43+H46 -> 974.65456 | I49: =I40-I43+I46 -> 938.41869 | J49: =J40-J43+J46 -> 904.4131 | K49: =K40-K43+K46 -> 872.405 | L49: =L40-L43+L46 -> 842.18977 | M49: =M40-M43+M46 -> 813.58746 | N49: =N40-N43+N46 -> 786.43973 | O49: =O40-O43+O46 -> 760.60718 | ... Q49: =Q40-Q43+Q46 -> 712.41081
A50: Book/cash tax (same timing assumption) | B50: =IF(ISNUMBER(History!B45),History!B45,"") -> 348 | C50: =IF(ISNUMBER(History!C45),History!C45,"") -> 251 | D50: =IF(ISNUMBER(History!D45),History!D45,"") -> 143 | E50: =IF(ISNUMBER(History!E45),History!E45,"") -> 230 | F50: =IF(ISNUMBER(History!F45),History!F45,"") -> 233 | G50: =Inputs!$B$30 -> 190 | H50: =MAX(0,H49)*H51 -> 190.71511 | I50: =MAX(0,I49)*I51 -> 183.62467 | J50: =MAX(0,J49)*J51 -> 176.97064 | K50: =MAX(0,K49)*K51 -> 170.70747 | L50: =MAX(0,L49)*L51 -> 164.79511 | M50: =MAX(0,M49)*M51 -> 159.19837 | N50: =MAX(0,N49)*N51 -> 153.88625 | O50: =MAX(0,O49)*O51 -> 148.83148 | ... Q50: =MAX(0,Q49)*Q51 -> 139.40067
A51: Tax rate | B51: =IF(AND(COUNT(B50,B49)=2,B49<>0),B50/B49,"") -> 0.24455376 | C51: =IF(AND(COUNT(C50,C49)=2,C49<>0),C50/C49,"") -> 0.24019139 | D51: =IF(AND(COUNT(D50,D49)=2,D49<>0),D50/D49,"") -> 0.14005877 | E51: =IF(AND(COUNT(E50,E49)=2,E49<>0),E50/E49,"") -> 0.22373541 | F51: =IF(AND(COUNT(F50,F49)=2,F49<>0),F50/F49,"") -> 0.26417234 | G51: =IF(AND(COUNT(G50,G49)=2,G49<>0),G50/G49,"") -> 0.19567456 | H51: =Inputs!$B$52 -> 0.19567456 | I51: =Inputs!$B$52 -> 0.19567456 | J51: =Inputs!$B$52 -> 0.19567456 | K51: =Inputs!$B$52 -> 0.19567456 | L51: =Inputs!$B$52 -> 0.19567456 | M51: =Inputs!$B$52 -> 0.19567456 | N51: =Inputs!$B$52 -> 0.19567456 | O51: =Inputs!$B$52 -> 0.19567456 | ... Q51: =Inputs!$B$52 -> 0.19567456
A53: Net income | B53: =IF(ISNUMBER(History!B13),History!B13,"") -> 1333 | C53: =IF(ISNUMBER(History!C13),History!C13,"") -> 800 | D53: =IF(ISNUMBER(History!D13),History!D13,"") -> 878 | E53: =IF(ISNUMBER(History!E13),History!E13,"") -> 798 | F53: =IF(ISNUMBER(History!F13),History!F13,"") -> 649 | G53: =IF(ISNUMBER(History!G13),History!G13,"") -> 781 | H53: =H49-H50 -> 783.93946 | I53: =I49-I50 -> 754.79402 | J53: =J49-J50 -> 727.44246 | K53: =K49-K50 -> 701.69753 | L53: =L49-L50 -> 677.39465 | M53: =M49-M50 -> 654.38909 | N53: =N49-N50 -> 632.55348 | O53: =O49-O50 -> 611.7757 | ... Q53: =Q49-Q50 -> 573.01014
A54: Net income margin | B54: =IF(AND(COUNT(B53,B8)=2,B8<>0),B53/B8,"") -> 0.16911951 | C54: =IF(AND(COUNT(C53,C8)=2,C8<>0),C53/C8,"") -> 0.10582011 | D54: =IF(AND(COUNT(D53,D8)=2,D8<>0),D53/D8,"") -> 0.11818549 | E54: =IF(AND(COUNT(E53,E8)=2,E8<>0),E53/E8,"") -> 0.10921035 | F54: =IF(AND(COUNT(F53,F8)=2,F8<>0),F53/F8,"") -> 0.089013853 | G54: =IF(AND(COUNT(G53,G8)=2,G8<>0),G53/G8,"") -> 0.1083368 | H54: =IF(AND(COUNT(H53,H8)=2,H8<>0),H53/H8,"") -> 0.11230892 | I54: =IF(AND(COUNT(I53,I8)=2,I8<>0),I53/I8,"") -> 0.11034028 | ... Q54: =IF(AND(COUNT(Q53,Q8)=2,Q8<>0),Q53/Q8,"") -> 0.098459887
A56: Reported discontinued-operations income | B56: =IF(ISNUMBER(History!B14),History!B14,"") -> 258 | C56: =IF(ISNUMBER(History!C14),History!C14,"") -> 6 | D56: =IF(ISNUMBER(History!D14),History!D14,"") | E56: =IF(ISNUMBER(History!E14),History!E14,"") | F56: =IF(ISNUMBER(History!F14),History!F14,"") | G56: =IF(ISNUMBER(History!G14),History!G14,"")
A57: Reported continuing-operations income | B57: =IF(ISNUMBER(History!B4),History!B4,"") -> 1075 | C57: =IF(ISNUMBER(History!C4),History!C4,"") -> 794 | D57: =IF(ISNUMBER(History!D4),History!D4,"") | E57: =IF(ISNUMBER(History!E4),History!E4,"") | F57: =IF(ISNUMBER(History!F4),History!F4,"") | G57: =IF(ISNUMBER(History!G4),History!G4,"")
A59: Revenue grows from the preceding fiscal year; first full year uses YTD + Stub. Gross profit retains embedded D&A ratios; total D&A is replaced once below EBITDA. SBC remains expensed. EBITDA uses the disclosed D&A aggregate as a proxy; no issuer-adjusted EBITDA is claimed. Each FY/YTD reconciles to reported EBIT. Expense magnitudes are presentation conversions; signed facts remain in History/Evidence. Absent categories are not asserted to be zero. Forecast ratios start at TTM and include embedded D&A/SBC; total D&A is replaced once below EBITDA. No allocation of D&A between COGS and SG&A is claimed.

Sheet BalanceSheet
A1: BBWI — BalanceSheet
A2: USD millions. Actuals | TTM / latest balances | annual forecasts. Blank = unavailable or not comparable.
A3: Line | B3: FY2021A 2022-01-29 | C3: FY2022A 2023-01-28 | D3: FY2023A 2024-02-03 | E3: FY2024A 2025-02-01 | F3: FY2025A 2026-01-31 | G3: Latest balance 2026-08-01 | H3: FY2027E 2028-01-29 | I3: FY2028E 2029-01-27 | J3: FY2029E 2030-01-26 | K3: FY2030E 2031-01-25 | L3: FY2031E 2032-01-24 | M3: FY2032E 2033-01-22 | N3: FY2033E 2034-01-21 | O3: FY2034E 2035-01-20 | P3: FY2035E 2036-01-19 | Q3: FY2036E 2037-01-17
A6: Cash | B6: =IF(ISNUMBER(History!B17),History!B17,"") -> 1979 | C6: =IF(ISNUMBER(History!C17),History!C17,"") -> 1232 | D6: =IF(ISNUMBER(History!D17),History!D17,"") -> 1084 | E6: =IF(ISNUMBER(History!E17),History!E17,"") -> 674 | F6: =IF(ISNUMBER(History!F17),History!F17,"") -> 953 | G6: =Inputs!$B$4 -> 794 | H6: =CashFlow!H30 -> 1997.6799 | I6: =CashFlow!I30 -> 2711.0018 | J6: =CashFlow!J30 -> 3408.3406 | K6: =CashFlow!K30 -> 4089.7582 | L6: =CashFlow!L30 -> 4755.3474 | M6: =CashFlow!M30 -> 5405.2275 | N6: =CashFlow!N30 -> 6039.5399 | O6: =CashFlow!O30 -> 6658.4449 | ... Q6: =CashFlow!Q30 -> 7850.7495
A7: Marketable securities | G7: =Inputs!$B$5+Inputs!$B$6 -> 0 | H7: =Inputs!$B$5+Inputs!$B$6 -> 0 | I7: =Inputs!$B$5+Inputs!$B$6 -> 0 | J7: =Inputs!$B$5+Inputs!$B$6 -> 0 | K7: =Inputs!$B$5+Inputs!$B$6 -> 0 | L7: =Inputs!$B$5+Inputs!$B$6 -> 0 | M7: =Inputs!$B$5+Inputs!$B$6 -> 0 | N7: =Inputs!$B$5+Inputs!$B$6 -> 0 | ... Q7: =Inputs!$B$5+Inputs!$B$6 -> 0
A8: Operating current assets | B8: =IF(ISNUMBER(WorkingCapital!B8),WorkingCapital!B8,"") -> 1030 | C8: =IF(ISNUMBER(WorkingCapital!C8),WorkingCapital!C8,"") -> 1034 | D8: =IF(ISNUMBER(WorkingCapital!D8),WorkingCapital!D8,"") -> 1031 | E8: =IF(ISNUMBER(WorkingCapital!E8),WorkingCapital!E8,"") -> 1149 | F8: =IF(ISNUMBER(WorkingCapital!F8),WorkingCapital!F8,"") -> 1066 | G8: =Inputs!$B$7 -> 1256 | H8: =WorkingCapital!H8 -> 1216.1381 | I8: =WorkingCapital!I8 -> 1191.8154 | J8: =WorkingCapital!J8 -> 1167.9791 | K8: =WorkingCapital!K8 -> 1144.6195 | L8: =WorkingCapital!L8 -> 1121.7271 | M8: =WorkingCapital!M8 -> 1099.2925 | N8: =WorkingCapital!N8 -> 1077.3067 | O8: =WorkingCapital!O8 -> 1055.7606 | ... Q8: =WorkingCapital!Q8 -> 1013.9524
A9: Other modeled current assets | G9: =Inputs!$B$8+Inputs!$B$9+Inputs!$B$10 -> 0 | H9: =WorkingCapital!H10+WorkingCapital!H12+WorkingCapital!H14 -> 0 | I9: =WorkingCapital!I10+WorkingCapital!I12+WorkingCapital!I14 -> 0 | J9: =WorkingCapital!J10+WorkingCapital!J12+WorkingCapital!J14 -> 0 | K9: =WorkingCapital!K10+WorkingCapital!K12+WorkingCapital!K14 -> 0 | L9: =WorkingCapital!L10+WorkingCapital!L12+WorkingCapital!L14 -> 0 | M9: =WorkingCapital!M10+WorkingCapital!M12+WorkingCapital!M14 -> 0 | N9: =WorkingCapital!N10+WorkingCapital!N12+WorkingCapital!N14 -> 0 | O9: =WorkingCapital!O10+WorkingCapital!O12+WorkingCapital!O14 -> 0 | ... Q9: =WorkingCapital!Q10+WorkingCapital!Q12+WorkingCapital!Q14 -> 0
A10: PP&E | B10: =IF(ISNUMBER(History!B23),History!B23,"") -> 1009 | C10: =IF(ISNUMBER(History!C23),History!C23,"") -> 1193 | D10: =IF(ISNUMBER(History!D23),History!D23,"") -> 1220 | E10: =IF(ISNUMBER(History!E23),History!E23,"") -> 1127 | F10: =IF(ISNUMBER(History!F23),History!F23,"") -> 1127 | G10: =Inputs!$B$11 -> 1106 | H10: =Assets!H14 -> 1247.3241 | I10: =Assets!I14 -> 1306.6897 | J10: =Assets!J14 -> 1354.329 | K10: =Assets!K14 -> 1391.7939 | L10: =Assets!L14 -> 1420.4406 | M10: =Assets!M14 -> 1441.454 | N10: =Assets!N14 -> 1455.8693 | O10: =Assets!O14 -> 1464.5908 | ... Q10: =Assets!Q14 -> 1468.0102
A11: Finite intangibles | G11: =Inputs!$B$12 -> 0 | H11: =Assets!H22 -> 0 | I11: =Assets!I22 -> 0 | J11: =Assets!J22 -> 0 | K11: =Assets!K22 -> 0 | L11: =Assets!L22 -> 0 | M11: =Assets!M22 -> 0 | N11: =Assets!N22 -> 0 | O11: =Assets!O22 -> 0 | ... Q11: =Assets!Q22 -> 0
A14: Other noncurrent assets | G14: =Inputs!$B$14 -> 2000 | H14: =Inputs!$B$14 -> 2000 | I14: =Inputs!$B$14 -> 2000 | J14: =Inputs!$B$14 -> 2000 | K14: =Inputs!$B$14 -> 2000 | L14: =Inputs!$B$14 -> 2000 | M14: =Inputs!$B$14 -> 2000 | N14: =Inputs!$B$14 -> 2000 | ... Q14: =Inputs!$B$14 -> 2000
A15: Total assets | B15: =IF(ISNUMBER(History!B25),History!B25,"") -> 6026 | C15: =IF(ISNUMBER(History!C25),History!C25,"") -> 5494 | D15: =IF(ISNUMBER(History!D25),History!D25,"") -> 5463 | E15: =IF(ISNUMBER(History!E25),History!E25,"") -> 4872 | F15: =IF(ISNUMBER(History!F25),History!F25,"") -> 5069 | G15: =Inputs!$B$23 -> 5156 | H15: =SUM(H6:H11)+H14 -> 6461.1421 | I15: =SUM(I6:I11)+I14 -> 7209.5069 | J15: =SUM(J6:J11)+J14 -> 7930.6487 | K15: =SUM(K6:K11)+K14 -> 8626.1715 | L15: =SUM(L6:L11)+L14 -> 9297.515 | M15: =SUM(M6:M11)+M14 -> 9945.974 | N15: =SUM(N6:N11)+N14 -> 10572.716 | O15: =SUM(O6:O11)+O14 -> 11178.796 | ... Q15: =SUM(Q6:Q11)+Q14 -> 12332.712
A18: Operating current liabilities | B18: =IF(ISNUMBER(WorkingCapital!B18),WorkingCapital!B18,"") -> 1290 | C18: =IF(ISNUMBER(WorkingCapital!C18),WorkingCapital!C18,"") -> 1379 | D18: =IF(ISNUMBER(WorkingCapital!D18),WorkingCapital!D18,"") -> 1289 | E18: =IF(ISNUMBER(WorkingCapital!E18),WorkingCapital!E18,"") -> 1231 | F18: =IF(ISNUMBER(WorkingCapital!F18),WorkingCapital!F18,"") -> 1311 | G18: =Inputs!$B$15 -> 1459 | H18: =WorkingCapital!H18 -> 1412.6955 | I18: =WorkingCapital!I18 -> 1384.4416 | J18: =WorkingCapital!J18 -> 1356.7527 | K18: =WorkingCapital!K18 -> 1329.6177 | L18: =WorkingCapital!L18 -> 1303.0253 | M18: =WorkingCapital!M18 -> 1276.9648 | N18: =WorkingCapital!N18 -> 1251.4255 | O18: =WorkingCapital!O18 -> 1226.397 | ... Q18: =WorkingCapital!Q18 -> 1177.8317
A20: Debt | G20: =Inputs!$B$18+Inputs!$B$19+Inputs!$B$20 -> 3614 | H20: =Inputs!$B$18+Inputs!$B$19+Inputs!$B$20 -> 3614 | I20: =Inputs!$B$18+Inputs!$B$19+Inputs!$B$20 -> 3614 | J20: =Inputs!$B$18+Inputs!$B$19+Inputs!$B$20 -> 3614 | K20: =Inputs!$B$18+Inputs!$B$19+Inputs!$B$20 -> 3614 | L20: =Inputs!$B$18+Inputs!$B$19+Inputs!$B$20 -> 3614 | M20: =Inputs!$B$18+Inputs!$B$19+Inputs!$B$20 -> 3614 | N20: =Inputs!$B$18+Inputs!$B$19+Inputs!$B$20 -> 3614 | ... Q20: =Inputs!$B$18+Inputs!$B$19+Inputs!$B$20 -> 3614
A21: Other current liabilities (held flat; includes tax/accrual uncertainty) | G21: =Inputs!$B$17 -> 0 | H21: =Inputs!$B$17 -> 0 | I21: =Inputs!$B$17 -> 0 | J21: =Inputs!$B$17 -> 0 | K21: =Inputs!$B$17 -> 0 | L21: =Inputs!$B$17 -> 0 | M21: =Inputs!$B$17 -> 0 | N21: =Inputs!$B$17 -> 0 | ... Q21: =Inputs!$B$17 -> 0
A22: Other noncurrent liabilities | G22: =Inputs!$B$21 -> 1137 | H22: =Inputs!$B$21 -> 1137 | I22: =Inputs!$B$21 -> 1137 | J22: =Inputs!$B$21 -> 1137 | K22: =Inputs!$B$21 -> 1137 | L22: =Inputs!$B$21 -> 1137 | M22: =Inputs!$B$21 -> 1137 | N22: =Inputs!$B$21 -> 1137 | ... Q22: =Inputs!$B$21 -> 1137
A23: Deferred revenue | G23: =Inputs!$B$16 -> 0 | H23: =WorkingCapital!H20 -> 0 | I23: =WorkingCapital!I20 -> 0 | J23: =WorkingCapital!J20 -> 0 | K23: =WorkingCapital!K20 -> 0 | L23: =WorkingCapital!L20 -> 0 | M23: =WorkingCapital!M20 -> 0 | N23: =WorkingCapital!N20 -> 0 | O23: =WorkingCapital!O20 -> 0 | ... Q23: =WorkingCapital!Q20 -> 0
A24: Total liabilities | B24: =IF(ISNUMBER(History!B26),History!B26,"") -> 7543 | C24: =IF(ISNUMBER(History!C26),History!C26,"") -> 7699 | D24: =IF(ISNUMBER(History!D26),History!D26,"") -> 7089 | E24: =IF(ISNUMBER(History!E26),History!E26,"") -> 6255 | F24: =IF(ISNUMBER(History!F26),History!F26,"") -> 6348 | G24: =Inputs!$B$24 -> 6210 | H24: =H18+SUM(H20:H23) -> 6163.6955 | I24: =I18+SUM(I20:I23) -> 6135.4416 | J24: =J18+SUM(J20:J23) -> 6107.7527 | K24: =K18+SUM(K20:K23) -> 6080.6177 | L24: =L18+SUM(L20:L23) -> 6054.0253 | M24: =M18+SUM(M20:M23) -> 6027.9648 | N24: =N18+SUM(N20:N23) -> 6002.4255 | O24: =O18+SUM(O20:O23) -> 5977.397 | ... Q24: =Q18+SUM(Q20:Q23) -> 5928.8317
A26: Opening equity | C26: =IF(ISNUMBER(B29),B29,"") -> -1517 | D26: =IF(ISNUMBER(C29),C29,"") -> -2205 | E26: =IF(ISNUMBER(D29),D29,"") -> -1626 | F26: =IF(ISNUMBER(E29),E29,"") -> -1383 | H26: =Stub!B48 -> -508.76285 | I26: =H29 -> 297.44666 | J26: =I29 -> 1074.0653 | K26: =J29 -> 1822.8959 | L26: =K29 -> 2545.5539 | M26: =L29 -> 3243.4897 | N26: =M29 -> 3918.0091 | O26: =N29 -> 4570.2904 | P26: =O29 -> 5201.3993 | Q26: =P29 -> 5812.3028
A27: Net income + SBC equity contribution | H27: =Income!H53+CashFlow!H11 -> 806.2095 | I27: =Income!I53+CashFlow!I11 -> 776.61866 | J27: =Income!J53+CashFlow!J11 -> 748.83061 | K27: =Income!K53+CashFlow!K11 -> 722.65792 | L27: =Income!L53+CashFlow!L11 -> 697.93583 | M27: =Income!M53+CashFlow!M11 -> 674.51944 | N27: =Income!N53+CashFlow!N11 -> 652.28123 | O27: =Income!O53+CashFlow!O11 -> 631.1089 | ... Q27: =Income!Q53+CashFlow!Q11 -> 591.57774
A28: Shareholder distributions (equity deduction) | H28: =CashFlow!H24 -> 0 | I28: =CashFlow!I24 -> 0 | J28: =CashFlow!J24 -> 0 | K28: =CashFlow!K24 -> 0 | L28: =CashFlow!L24 -> 0 | M28: =CashFlow!M24 -> 0 | N28: =CashFlow!N24 -> 0 | O28: =CashFlow!O24 -> 0 | ... Q28: =CashFlow!Q24 -> 0
A29: Closing equity | B29: =IF(ISNUMBER(History!B51),History!B51,"") -> -1517 | C29: =IF(ISNUMBER(History!C51),History!C51,"") -> -2205 | D29: =IF(ISNUMBER(History!D51),History!D51,"") -> -1626 | E29: =IF(ISNUMBER(History!E51),History!E51,"") -> -1383 | F29: =IF(ISNUMBER(History!F51),History!F51,"") -> -1279 | G29: =Inputs!$B$22 -> -1054 | H29: =H26+H27-H28 -> 297.44666 | I29: =I26+I27-I28 -> 1074.0653 | J29: =J26+J27-J28 -> 1822.8959 | K29: =K26+K27-K28 -> 2545.5539 | L29: =L26+L27-L28 -> 3243.4897 | M29: =M26+M27-M28 -> 3918.0091 | N29: =N26+N27-N28 -> 4570.2904 | O29: =O26+O27-O28 -> 5201.3993 | ... Q29: =Q26+Q27-Q28 -> 6403.8805
A32: Balance check | B32: =IF(COUNT(B15,B24,B29)=3,B15-B24-B29,"") -> 0 | C32: =IF(COUNT(C15,C24,C29)=3,C15-C24-C29,"") -> 0 | D32: =IF(COUNT(D15,D24,D29)=3,D15-D24-D29,"") -> 0 | E32: =IF(COUNT(E15,E24,E29)=3,E15-E24-E29,"") -> 0 | F32: =IF(COUNT(F15,F24,F29)=3,F15-F24-F29,"") -> 0 | G32: =IF(COUNT(G15,G24,G29)=3,G15-G24-G29,"") -> 0 | H32: =H15-H24-H29 -> -8.5265128e-13 | I32: =I15-I24-I29 -> 0 | J32: =J15-J24-J29 -> 0 | K32: =K15-K24-K29 -> 0 | L32: =L15-L24-L29 -> 0 | M32: =M15-M24-M29 -> 0 | N32: =N15-N24-N29 -> 0 | O32: =O15-O24-O29 -> 0 | ... Q32: =Q15-Q24-Q29 -> 0
A36: Reported accounts receivable (included above) | B36: =IF(ISNUMBER(History!B18),History!B18,"") -> 240 | C36: =IF(ISNUMBER(History!C18),History!C18,"") -> 226 | D36: =IF(ISNUMBER(History!D18),History!D18,"") -> 224 | E36: =IF(ISNUMBER(History!E18),History!E18,"") -> 205 | F36: =IF(ISNUMBER(History!F18),History!F18,"") -> 180
A37: Reported inventory (included above) | B37: =IF(ISNUMBER(History!B19),History!B19,"") -> 709 | C37: =IF(ISNUMBER(History!C19),History!C19,"") -> 709 | D37: =IF(ISNUMBER(History!D19),History!D19,"") -> 710 | E37: =IF(ISNUMBER(History!E19),History!E19,"") -> 734 | F37: =IF(ISNUMBER(History!F19),History!F19,"") -> 699
A38: Reported accounts payable (included above) | B38: =IF(ISNUMBER(History!B20),History!B20,"") -> 435 | C38: =IF(ISNUMBER(History!C20),History!C20,"") -> 455 | D38: =IF(ISNUMBER(History!D20),History!D20,"") -> 380 | E38: =IF(ISNUMBER(History!E20),History!E20,"") -> 338 | F38: =IF(ISNUMBER(History!F20),History!F20,"") -> 465

Sheet CashFlow
A1: BBWI — CashFlow
A2: USD millions. Actuals | TTM / latest balances | annual forecasts. Blank = unavailable or not comparable.
A3: Line | B3: FY2021A 2022-01-29 | C3: FY2022A 2023-01-28 | D3: FY2023A 2024-02-03 | E3: FY2024A 2025-02-01 | F3: FY2025A 2026-01-31 | G3: TTM 2026-08-01 | H3: FY2027E 2028-01-29 | I3: FY2028E 2029-01-27 | J3: FY2029E 2030-01-26 | K3: FY2030E 2031-01-25 | L3: FY2031E 2032-01-24 | M3: FY2032E 2033-01-22 | N3: FY2033E 2034-01-21 | O3: FY2034E 2035-01-20 | P3: FY2035E 2036-01-19 | Q3: FY2036E 2037-01-17
A8: Net income | B8: =IF(ISNUMBER(History!B13),History!B13,"") -> 1333 | C8: =IF(ISNUMBER(History!C13),History!C13,"") -> 800 | D8: =IF(ISNUMBER(History!D13),History!D13,"") -> 878 | E8: =IF(ISNUMBER(History!E13),History!E13,"") -> 798 | F8: =IF(ISNUMBER(History!F13),History!F13,"") -> 649 | G8: =IF(ISNUMBER(History!G13),History!G13,"") -> 781 | H8: =Income!H53 -> 783.93946 | I8: =Income!I53 -> 754.79402 | J8: =Income!J53 -> 727.44246 | K8: =Income!K53 -> 701.69753 | L8: =Income!L53 -> 677.39465 | M8: =Income!M53 -> 654.38909 | N8: =Income!N53 -> 632.55348 | O8: =Income!O53 -> 611.7757 | ... Q8: =Income!Q53 -> 573.01014
A9: Depreciation and amortization | B9: =IF(ISNUMBER(History!B33),History!B33,"") -> 363 | C9: =IF(ISNUMBER(History!C33),History!C33,"") -> 221 | D9: =IF(ISNUMBER(History!D33),History!D33,"") -> 269 | E9: =IF(ISNUMBER(History!E33),History!E33,"") -> 282 | F9: =IF(ISNUMBER(History!F33),History!F33,"") -> 254 | G9: =IF(ISNUMBER(History!G33),History!G33,"") -> 246 | H9: =Assets!H13+Assets!H21 -> 161.45204 | I9: =Assets!I13+Assets!I21 -> 170.26759 | J9: =Assets!J13+Assets!J21 -> 177.40125 | K9: =Assets!K13+Assets!K21 -> 183.07486 | L9: =Assets!L13+Assets!L21 -> 187.4823 | M9: =Assets!M13+Assets!M21 -> 190.79297 | N9: =Assets!N13+Assets!N21 -> 193.15488 | O9: =Assets!O13+Assets!O21 -> 194.69734 | ... Q9: =Assets!Q13+Assets!Q21 -> 195.76122
A11: SBC cash-flow addback / equity contribution | B11: =IF(ISNUMBER(History!B34),History!B34,"") -> 46 | C11: =IF(ISNUMBER(History!C34),History!C34,"") -> 38 | D11: =IF(ISNUMBER(History!D34),History!D34,"") -> 43 | E11: =IF(ISNUMBER(History!E34),History!E34,"") -> 40 | F11: =IF(ISNUMBER(History!F34),History!F34,"") -> 31 | G11: =IF(ISNUMBER(History!G34),History!G34,"") -> 23 | H11: =Income!H8*H12 -> 22.270045 | I11: =Income!I8*I12 -> 21.824644 | J11: =Income!J8*J12 -> 21.388151 | K11: =Income!K8*K12 -> 20.960388 | L11: =Income!L8*L12 -> 20.541181 | M11: =Income!M8*M12 -> 20.130357 | N11: =Income!N8*N12 -> 19.72775 | O11: =Income!O8*O12 -> 19.333195 | ... Q11: =Income!Q8*Q12 -> 18.5676
A12: SBC / revenue | H12: =Inputs!$B$32/Inputs!$B$27 -> 0.0031904564 | I12: =Inputs!$B$32/Inputs!$B$27 -> 0.0031904564 | J12: =Inputs!$B$32/Inputs!$B$27 -> 0.0031904564 | K12: =Inputs!$B$32/Inputs!$B$27 -> 0.0031904564 | L12: =Inputs!$B$32/Inputs!$B$27 -> 0.0031904564 | M12: =Inputs!$B$32/Inputs!$B$27 -> 0.0031904564 | N12: =Inputs!$B$32/Inputs!$B$27 -> 0.0031904564 | O12: =Inputs!$B$32/Inputs!$B$27 -> 0.0031904564 | ... Q12: =Inputs!$B$32/Inputs!$B$27 -> 0.0031904564
A13: Change in operating NWC (cash use) | H13: =WorkingCapital!H25 -> 41.70703 | I13: =WorkingCapital!I25 -> 3.9311471 | J13: =WorkingCapital!J25 -> 3.8525242 | K13: =WorkingCapital!K25 -> 3.7754737 | L13: =WorkingCapital!L25 -> 3.6999642 | M13: =WorkingCapital!M25 -> 3.6259649 | N13: =WorkingCapital!N25 -> 3.5534456 | O13: =WorkingCapital!O25 -> 3.4823767 | ... Q13: =WorkingCapital!Q25 -> 3.3444746
A14: CFO | B14: =IF(ISNUMBER(History!B36),History!B36,"") -> 1492 | C14: =IF(ISNUMBER(History!C36),History!C36,"") -> 1144 | D14: =IF(ISNUMBER(History!D36),History!D36,"") -> 954 | E14: =IF(ISNUMBER(History!E36),History!E36,"") -> 886 | F14: =IF(ISNUMBER(History!F36),History!F36,"") -> 1102 | G14: =IF(ISNUMBER(History!G36),History!G36,"") -> 1273 | H14: =Income!H53+Assets!H13+Assets!H21+H11-WorkingCapital!H25 -> 925.95452 | I14: =Income!I53+Assets!I13+Assets!I21+I11-WorkingCapital!I25 -> 942.95511 | J14: =Income!J53+Assets!J13+Assets!J21+J11-WorkingCapital!J25 -> 922.37934 | K14: =Income!K53+Assets!K13+Assets!K21+K11-WorkingCapital!K25 -> 901.95731 | L14: =Income!L53+Assets!L13+Assets!L21+L11-WorkingCapital!L25 -> 881.71817 | M14: =Income!M53+Assets!M13+Assets!M21+M11-WorkingCapital!M25 -> 861.68645 | N14: =Income!N53+Assets!N13+Assets!N21+N11-WorkingCapital!N25 -> 841.88267 | O14: =Income!O53+Assets!O13+Assets!O21+O11-WorkingCapital!O25 -> 822.32386 | ... Q14: =Income!Q53+Assets!Q13+Assets!Q21+Q11-WorkingCapital!Q25 -> 783.99448
A17: Cash PP&E additions (cash use) | B17: =IF(ISNUMBER(Assets!B11),Assets!B11,"") -> 270 | C17: =IF(ISNUMBER(Assets!C11),Assets!C11,"") -> 328 | D17: =IF(ISNUMBER(Assets!D11),Assets!D11,"") -> 298 | E17: =IF(ISNUMBER(Assets!E11),Assets!E11,"") -> 226 | F17: =IF(ISNUMBER(Assets!F11),Assets!F11,"") -> 237 | G17: =IF(ISNUMBER(Assets!G11),Assets!G11,"") -> 242 | H17: =Assets!H11 -> 234.31961 | I17: =Assets!I11 -> 229.63321 | J17: =Assets!J11 -> 225.04055 | K17: =Assets!K11 -> 220.53974 | L17: =Assets!L11 -> 216.12894 | M17: =Assets!M11 -> 211.80637 | N17: =Assets!N11 -> 207.57024 | O17: =Assets!O11 -> 203.41883 | ... Q17: =Assets!Q11 -> 195.36345
A18: Cash intangible additions (cash use) | H18: =Assets!H19 -> 0 | I18: =Assets!I19 -> 0 | J18: =Assets!J19 -> 0 | K18: =Assets!K19 -> 0 | L18: =Assets!L19 -> 0 | M18: =Assets!M19 -> 0 | N18: =Assets!N19 -> 0 | O18: =Assets!O19 -> 0 | ... Q18: =Assets!Q19 -> 0
A20: CFI | B20: =IF(ISNUMBER(History!B37),History!B37,"") -> -259 | C20: =IF(ISNUMBER(History!C37),History!C37,"") -> -328 | D20: =IF(ISNUMBER(History!D37),History!D37,"") -> -286 | E20: =IF(ISNUMBER(History!E37),History!E37,"") -> -162 | F20: =IF(ISNUMBER(History!F37),History!F37,"") -> -227 | G20: =IF(ISNUMBER(History!G37),History!G37,"") -> -221 | H20: =-Assets!H11-Assets!H19 -> -234.31961 | I20: =-Assets!I11-Assets!I19 -> -229.63321 | J20: =-Assets!J11-Assets!J19 -> -225.04055 | K20: =-Assets!K11-Assets!K19 -> -220.53974 | L20: =-Assets!L11-Assets!L19 -> -216.12894 | M20: =-Assets!M11-Assets!M19 -> -211.80637 | N20: =-Assets!N11-Assets!N19 -> -207.57024 | O20: =-Assets!O11-Assets!O19 -> -203.41883 | ... Q20: =-Assets!Q11-Assets!Q19 -> -195.36345
A23: Distribution payout ratio | H23: =Inputs!$B$59 -> 0 | I23: =Inputs!$B$59 -> 0 | J23: =Inputs!$B$59 -> 0 | K23: =Inputs!$B$59 -> 0 | L23: =Inputs!$B$59 -> 0 | M23: =Inputs!$B$59 -> 0 | N23: =Inputs!$B$59 -> 0 | O23: =Inputs!$B$59 -> 0 | ... Q23: =Inputs!$B$59 -> 0
A24: Cash shareholder distributions (dividend-equivalent policy) | H24: =MAX(0,Income!H53)*H23 -> 0 | I24: =MAX(0,Income!I53)*I23 -> 0 | J24: =MAX(0,Income!J53)*J23 -> 0 | K24: =MAX(0,Income!K53)*K23 -> 0 | L24: =MAX(0,Income!L53)*L23 -> 0 | M24: =MAX(0,Income!M53)*M23 -> 0 | N24: =MAX(0,Income!N53)*N23 -> 0 | O24: =MAX(0,Income!O53)*O23 -> 0 | ... Q24: =MAX(0,Income!Q53)*Q23 -> 0
A25: CFF (zero net debt issuance; refinancing assumption) | B25: =IF(ISNUMBER(History!B38),History!B38,"") -> -3188 | C25: =IF(ISNUMBER(History!C38),History!C38,"") -> -1562 | D25: =IF(ISNUMBER(History!D38),History!D38,"") -> -815 | E25: =IF(ISNUMBER(History!E38),History!E38,"") -> -1132 | F25: =IF(ISNUMBER(History!F38),History!F38,"") -> -599 | G25: =IF(ISNUMBER(History!G38),History!G38,"") -> -621 | H25: =-H24 -> 0 | I25: =-I24 -> 0 | J25: =-J24 -> 0 | K25: =-K24 -> 0 | L25: =-L24 -> 0 | M25: =-M24 -> 0 | N25: =-N24 -> 0 | O25: =-O24 -> 0 | ... Q25: =-Q24 -> 0
A28: Opening cash | C28: =IF(ISNUMBER(B30),B30,"") -> 1979 | D28: =IF(ISNUMBER(C30),C30,"") -> 1232 | E28: =IF(ISNUMBER(D30),D30,"") -> 1084 | F28: =IF(ISNUMBER(E30),E30,"") -> 674 | H28: =Stub!B46 -> 1306.045 | I28: =H30 -> 1997.6799 | J28: =I30 -> 2711.0018 | K28: =J30 -> 3408.3406 | L28: =K30 -> 4089.7582 | M28: =L30 -> 4755.3474 | N28: =M30 -> 5405.2275 | O28: =N30 -> 6039.5399 | P28: =O30 -> 6658.4449 | Q28: =P30 -> 7262.1185
A30: Closing cash | B30: =IF(ISNUMBER(History!B17),History!B17,"") -> 1979 | C30: =IF(ISNUMBER(History!C17),History!C17,"") -> 1232 | D30: =IF(ISNUMBER(History!D17),History!D17,"") -> 1084 | E30: =IF(ISNUMBER(History!E17),History!E17,"") -> 674 | F30: =IF(ISNUMBER(History!F17),History!F17,"") -> 953 | G30: =Inputs!$B$4 -> 794 | H30: =H28+H14+H20+H25 -> 1997.6799 | I30: =I28+I14+I20+I25 -> 2711.0018 | J30: =J28+J14+J20+J25 -> 3408.3406 | K30: =K28+K14+K20+K25 -> 4089.7582 | L30: =L28+L14+L20+L25 -> 4755.3474 | M30: =M28+M14+M20+M25 -> 5405.2275 | N30: =N28+N14+N20+N25 -> 6039.5399 | O30: =O28+O14+O20+O25 -> 6658.4449 | ... Q30: =Q28+Q14+Q20+Q25 -> 7850.7495
A33: Cash FCF (CFO + CFI) | B33: =IF(ISNUMBER(History!B52),History!B52,"") -> 1233 | C33: =IF(ISNUMBER(History!C52),History!C52,"") -> 816 | D33: =IF(ISNUMBER(History!D52),History!D52,"") -> 668 | E33: =IF(ISNUMBER(History!E52),History!E52,"") -> 724 | F33: =IF(ISNUMBER(History!F52),History!F52,"") -> 875 | G33: =IF(ISNUMBER(History!G52),History!G52,"") -> 1052 | H33: =H14+H20 -> 691.63491 | I33: =I14+I20 -> 713.32189 | J33: =J14+J20 -> 697.33879 | K33: =K14+K20 -> 681.41757 | L33: =L14+L20 -> 665.58922 | M33: =M14+M20 -> 649.88008 | N33: =N14+N20 -> 634.31243 | O33: =O14+O20 -> 618.90503 | ... Q33: =Q14+Q20 -> 588.63103
A35: Economic UFCF (SBC remains expensed) | H35: =Income!H40-MAX(0,Income!H40)*Inputs!$B$52+Assets!H13+Assets!H21-Assets!H11-Assets!H19-WorkingCapital!H25 -> 858.30895 | I35: =Income!I40-MAX(0,Income!I40)*Inputs!$B$52+Assets!I13+Assets!I21-Assets!I11-Assets!I19-WorkingCapital!I25 -> 880.44134 | J35: =Income!J40-MAX(0,Income!J40)*Inputs!$B$52+Assets!J13+Assets!J21-Assets!J11-Assets!J19-WorkingCapital!J25 -> 864.89473 | K35: =Income!K40-MAX(0,Income!K40)*Inputs!$B$52+Assets!K13+Assets!K21-Assets!K11-Assets!K19-WorkingCapital!K25 -> 849.40127 | L35: =Income!L40-MAX(0,Income!L40)*Inputs!$B$52+Assets!L13+Assets!L21-Assets!L11-Assets!L19-WorkingCapital!L25 -> 833.99213 | M35: =Income!M40-MAX(0,Income!M40)*Inputs!$B$52+Assets!M13+Assets!M21-Assets!M11-Assets!M19-WorkingCapital!M25 -> 818.69381 | N35: =Income!N40-MAX(0,Income!N40)*Inputs!$B$52+Assets!N13+Assets!N21-Assets!N11-Assets!N19-WorkingCapital!N25 -> 803.52877 | O35: =Income!O40-MAX(0,Income!O40)*Inputs!$B$52+Assets!O13+Assets!O21-Assets!O11-Assets!O19-WorkingCapital!O25 -> 788.51592 | ... Q35: =Income!Q40-MAX(0,Income!Q40)*Inputs!$B$52+Assets!Q13+Assets!Q21-Assets!Q11-Assets!Q19-WorkingCapital!Q25 -> 759.00752

Sheet Assets
A1: BBWI — PP&E and finite intangibles
A2: USD millions. Actuals | TTM / latest balances | annual forecasts. Blank = unavailable or not comparable.
A3: Line | B3: FY2021A 2022-01-29 | C3: FY2022A 2023-01-28 | D3: FY2023A 2024-02-03 | E3: FY2024A 2025-02-01 | F3: FY2025A 2026-01-31 | G3: TTM 2026-08-01 | H3: FY2027E 2028-01-29 | I3: FY2028E 2029-01-27 | J3: FY2029E 2030-01-26 | K3: FY2030E 2031-01-25 | L3: FY2031E 2032-01-24 | M3: FY2032E 2033-01-22 | N3: FY2033E 2034-01-21 | O3: FY2034E 2035-01-20 | P3: FY2035E 2036-01-19 | Q3: FY2036E 2037-01-17
A6: Depreciation / amortization aggregate | B6: =IF(ISNUMBER(History!B33),History!B33,"") -> 363 | C6: =IF(ISNUMBER(History!C33),History!C33,"") -> 221 | D6: =IF(ISNUMBER(History!D33),History!D33,"") -> 269 | E6: =IF(ISNUMBER(History!E33),History!E33,"") -> 282 | F6: =IF(ISNUMBER(History!F33),History!F33,"") -> 254 | G6: =IF(ISNUMBER(History!G33),History!G33,"") -> 246 | H6: =Assets!H13+Assets!H21 -> 161.45204 | I6: =Assets!I13+Assets!I21 -> 170.26759 | J6: =Assets!J13+Assets!J21 -> 177.40125 | K6: =Assets!K13+Assets!K21 -> 183.07486 | L6: =Assets!L13+Assets!L21 -> 187.4823 | M6: =Assets!M13+Assets!M21 -> 190.79297 | N6: =Assets!N13+Assets!N21 -> 193.15488 | O6: =Assets!O13+Assets!O21 -> 194.69734 | ... Q6: =Assets!Q13+Assets!Q21 -> 195.76122
A8: Estimated embedded PP&E component (diagnostic) | H8: =Income!H8*Inputs!$B$53/Inputs!$B$27 -> 238.19266 | I8: =Income!I8*Inputs!$B$53/Inputs!$B$27 -> 233.42881 | J8: =Income!J8*Inputs!$B$53/Inputs!$B$27 -> 228.76023 | K8: =Income!K8*Inputs!$B$53/Inputs!$B$27 -> 224.18502 | L8: =Income!L8*Inputs!$B$53/Inputs!$B$27 -> 219.70132 | M8: =Income!M8*Inputs!$B$53/Inputs!$B$27 -> 215.3073 | N8: =Income!N8*Inputs!$B$53/Inputs!$B$27 -> 211.00115 | O8: =Income!O8*Inputs!$B$53/Inputs!$B$27 -> 206.78113 | ... Q8: =Income!Q8*Inputs!$B$53/Inputs!$B$27 -> 198.5926
A10: Opening PP&E | C10: =IF(ISNUMBER(B14),B14,"") -> 1009 | D10: =IF(ISNUMBER(C14),C14,"") -> 1193 | E10: =IF(ISNUMBER(D14),D14,"") -> 1220 | F10: =IF(ISNUMBER(E14),E14,"") -> 1127 | H10: =Stub!B21 -> 1174.4565 | I10: =H14 -> 1247.3241 | J10: =I14 -> 1306.6897 | K10: =J14 -> 1354.329 | L10: =K14 -> 1391.7939 | M10: =L14 -> 1420.4406 | N10: =M14 -> 1441.454 | O10: =N14 -> 1455.8693 | P10: =O14 -> 1464.5908 | Q10: =P14 -> 1468.408
A11: Cash PP&E additions (cash use) | B11: =IF(ISNUMBER(History!B35),-History!B35,"") -> 270 | C11: =IF(ISNUMBER(History!C35),-History!C35,"") -> 328 | D11: =IF(ISNUMBER(History!D35),-History!D35,"") -> 298 | E11: =IF(ISNUMBER(History!E35),-History!E35,"") -> 226 | F11: =IF(ISNUMBER(History!F35),-History!F35,"") -> 237 | G11: =-Inputs!$B$33 -> 242 | H11: =Income!H8*H12 -> 234.31961 | I11: =Income!I8*I12 -> 229.63321 | J11: =Income!J8*J12 -> 225.04055 | K11: =Income!K8*K12 -> 220.53974 | L11: =Income!L8*L12 -> 216.12894 | M11: =Income!M8*M12 -> 211.80637 | N11: =Income!N8*N12 -> 207.57024 | O11: =Income!O8*O12 -> 203.41883 | ... Q11: =Income!Q8*Q12 -> 195.36345
A12: Cash PP&E additions / revenue | B12: =IF(AND(ISNUMBER(B11),Income!B8<>0),B11/Income!B8,"") -> 0.034255265 | C12: =IF(AND(ISNUMBER(C11),Income!C8<>0),C11/Income!C8,"") -> 0.043386243 | D12: =IF(AND(ISNUMBER(D11),Income!D8<>0),D11/Income!D8,"") -> 0.04011307 | E12: =IF(AND(ISNUMBER(E11),Income!E8<>0),E11/Income!E8,"") -> 0.030929246 | F12: =IF(AND(ISNUMBER(F11),Income!F8<>0),F11/Income!F8,"") -> 0.032505829 | G12: =IF(AND(ISNUMBER(G11),Income!G8<>0),G11/Income!G8,"") -> 0.03356915 | H12: =-Inputs!$B$33/Inputs!$B$27 -> 0.03356915 | I12: =-Inputs!$B$33/Inputs!$B$27 -> 0.03356915 | J12: =-Inputs!$B$33/Inputs!$B$27 -> 0.03356915 | K12: =-Inputs!$B$33/Inputs!$B$27 -> 0.03356915 | L12: =-Inputs!$B$33/Inputs!$B$27 -> 0.03356915 | M12: =-Inputs!$B$33/Inputs!$B$27 -> 0.03356915 | N12: =-Inputs!$B$33/Inputs!$B$27 -> 0.03356915 | O12: =-Inputs!$B$33/Inputs!$B$27 -> 0.03356915 | ... Q12: =-Inputs!$B$33/Inputs!$B$27 -> 0.03356915
A13: PP&E depreciation: declining balance + half-period additions | H13: =MIN(H10,H10/H16*Income!H5)+MIN(H11,H11/H16*0.5*Income!H5) -> 161.45204 | I13: =MIN(I10,I10/I16*Income!I5)+MIN(I11,I11/I16*0.5*Income!I5) -> 170.26759 | J13: =MIN(J10,J10/J16*Income!J5)+MIN(J11,J11/J16*0.5*Income!J5) -> 177.40125 | K13: =MIN(K10,K10/K16*Income!K5)+MIN(K11,K11/K16*0.5*Income!K5) -> 183.07486 | L13: =MIN(L10,L10/L16*Income!L5)+MIN(L11,L11/L16*0.5*Income!L5) -> 187.4823 | M13: =MIN(M10,M10/M16*Income!M5)+MIN(M11,M11/M16*0.5*Income!M5) -> 190.79297 | N13: =MIN(N10,N10/N16*Income!N5)+MIN(N11,N11/N16*0.5*Income!N5) -> 193.15488 | O13: =MIN(O10,O10/O16*Income!O5)+MIN(O11,O11/O16*0.5*Income!O5) -> 194.69734 | ... Q13: =MIN(Q10,Q10/Q16*Income!Q5)+MIN(Q11,Q11/Q16*0.5*Income!Q5) -> 195.76122
A14: Closing PP&E | B14: =IF(ISNUMBER(History!B23),History!B23,"") -> 1009 | C14: =IF(ISNUMBER(History!C23),History!C23,"") -> 1193 | D14: =IF(ISNUMBER(History!D23),History!D23,"") -> 1220 | E14: =IF(ISNUMBER(History!E23),History!E23,"") -> 1127 | F14: =IF(ISNUMBER(History!F23),History!F23,"") -> 1127 | G14: =Inputs!$B$11 -> 1106 | H14: =H10+H11-H13 -> 1247.3241 | I14: =I10+I11-I13 -> 1306.6897 | J14: =J10+J11-J13 -> 1354.329 | K14: =K10+K11-K13 -> 1391.7939 | L14: =L10+L11-L13 -> 1420.4406 | M14: =M10+M11-M13 -> 1441.454 | N14: =N10+N11-N13 -> 1455.8693 | O14: =O10+O11-O13 -> 1464.5908 | ... Q14: =Q10+Q11-Q13 -> 1468.0102
A16: PP&E depreciation life (years) | H16: =Inputs!$B$56 -> 8 | I16: =Inputs!$B$56 -> 8 | J16: =Inputs!$B$56 -> 8 | K16: =Inputs!$B$56 -> 8 | L16: =Inputs!$B$56 -> 8 | M16: =Inputs!$B$56 -> 8 | N16: =Inputs!$B$56 -> 8 | O16: =Inputs!$B$56 -> 8 | ... Q16: =Inputs!$B$56 -> 8
A18: Opening finite intangibles | C18: =IF(ISNUMBER(B22),B22,"") | D18: =IF(ISNUMBER(C22),C22,"") | E18: =IF(ISNUMBER(D22),D22,"") | F18: =IF(ISNUMBER(E22),E22,"") | H18: =Stub!B25 -> 0 | I18: =H22 -> 0 | J18: =I22 -> 0 | K18: =J22 -> 0 | L18: =K22 -> 0 | M18: =L22 -> 0 | N18: =M22 -> 0 | O18: =N22 -> 0 | P18: =O22 -> 0 | Q18: =P22 -> 0
A19: Cash intangible additions (estimated) | H19: =Income!H8*H20 -> 0 | I19: =Income!I8*I20 -> 0 | J19: =Income!J8*J20 -> 0 | K19: =Income!K8*K20 -> 0 | L19: =Income!L8*L20 -> 0 | M19: =Income!M8*M20 -> 0 | N19: =Income!N8*N20 -> 0 | O19: =Income!O8*O20 -> 0 | ... Q19: =Income!Q8*Q20 -> 0
A20: Intangible additions / revenue | H20: =Inputs!$B$58 -> 0 | I20: =Inputs!$B$58 -> 0 | J20: =Inputs!$B$58 -> 0 | K20: =Inputs!$B$58 -> 0 | L20: =Inputs!$B$58 -> 0 | M20: =Inputs!$B$58 -> 0 | N20: =Inputs!$B$58 -> 0 | O20: =Inputs!$B$58 -> 0 | ... Q20: =Inputs!$B$58 -> 0
A21: Intangible amortization: declining balance | H21: =MIN(H18,H18/H24*Income!H5)+MIN(H19,H19/H24*0.5*Income!H5) -> 0 | I21: =MIN(I18,I18/I24*Income!I5)+MIN(I19,I19/I24*0.5*Income!I5) -> 0 | J21: =MIN(J18,J18/J24*Income!J5)+MIN(J19,J19/J24*0.5*Income!J5) -> 0 | K21: =MIN(K18,K18/K24*Income!K5)+MIN(K19,K19/K24*0.5*Income!K5) -> 0 | L21: =MIN(L18,L18/L24*Income!L5)+MIN(L19,L19/L24*0.5*Income!L5) -> 0 | M21: =MIN(M18,M18/M24*Income!M5)+MIN(M19,M19/M24*0.5*Income!M5) -> 0 | N21: =MIN(N18,N18/N24*Income!N5)+MIN(N19,N19/N24*0.5*Income!N5) -> 0 | O21: =MIN(O18,O18/O24*Income!O5)+MIN(O19,O19/O24*0.5*Income!O5) -> 0 | ... Q21: =MIN(Q18,Q18/Q24*Income!Q5)+MIN(Q19,Q19/Q24*0.5*Income!Q5) -> 0
A22: Closing total intangibles | B22: =IF(ISNUMBER(History!B24),History!B24,"") | C22: =IF(ISNUMBER(History!C24),History!C24,"") | D22: =IF(ISNUMBER(History!D24),History!D24,"") | E22: =IF(ISNUMBER(History!E24),History!E24,"") | F22: =IF(ISNUMBER(History!F24),History!F24,"") | G22: =Inputs!$B$12 -> 0 | H22: =H18+H19-H21 -> 0 | I22: =I18+I19-I21 -> 0 | J22: =J18+J19-J21 -> 0 | K22: =K18+K19-K21 -> 0 | L22: =L18+L19-L21 -> 0 | M22: =M18+M19-M21 -> 0 | N22: =N18+N19-N21 -> 0 | O22: =O18+O19-O21 -> 0 | ... Q22: =Q18+Q19-Q21 -> 0
A24: Intangible amortization life (years) | H24: =Inputs!$B$57 -> 5 | I24: =Inputs!$B$57 -> 5 | J24: =Inputs!$B$57 -> 5 | K24: =Inputs!$B$57 -> 5 | L24: =Inputs!$B$57 -> 5 | M24: =Inputs!$B$57 -> 5 | N24: =Inputs!$B$57 -> 5 | O24: =Inputs!$B$57 -> 5 | ... Q24: =Inputs!$B$57 -> 5

Sheet WorkingCapital
A1: BBWI — Working capital
A2: USD millions. Actuals | TTM / latest balances | annual forecasts. Blank = unavailable or not comparable.
A3: Line | B3: FY2021A 2022-01-29 | C3: FY2022A 2023-01-28 | D3: FY2023A 2024-02-03 | E3: FY2024A 2025-02-01 | F3: FY2025A 2026-01-31 | G3: TTM 2026-08-01 | H3: FY2027E 2028-01-29 | I3: FY2028E 2029-01-27 | J3: FY2029E 2030-01-26 | K3: FY2030E 2031-01-25 | L3: FY2031E 2032-01-24 | M3: FY2032E 2033-01-22 | N3: FY2033E 2034-01-21 | O3: FY2034E 2035-01-20 | P3: FY2035E 2036-01-19 | Q3: FY2036E 2037-01-17
A8: Operating current assets | B8: =IF(ISNUMBER(History!B43),History!B43,"") -> 1030 | C8: =IF(ISNUMBER(History!C43),History!C43,"") -> 1034 | D8: =IF(ISNUMBER(History!D43),History!D43,"") -> 1031 | E8: =IF(ISNUMBER(History!E43),History!E43,"") -> 1149 | F8: =IF(ISNUMBER(History!F43),History!F43,"") -> 1066 | G8: =Inputs!$B$7 -> 1256 | H8: =Inputs!$B$7*Income!H8/Income!H5/Inputs!$B$27 -> 1216.1381 | I8: =Inputs!$B$7*Income!I8/Income!I5/Inputs!$B$27 -> 1191.8154 | J8: =Inputs!$B$7*Income!J8/Income!J5/Inputs!$B$27 -> 1167.9791 | K8: =Inputs!$B$7*Income!K8/Income!K5/Inputs!$B$27 -> 1144.6195 | L8: =Inputs!$B$7*Income!L8/Income!L5/Inputs!$B$27 -> 1121.7271 | M8: =Inputs!$B$7*Income!M8/Income!M5/Inputs!$B$27 -> 1099.2925 | N8: =Inputs!$B$7*Income!N8/Income!N5/Inputs!$B$27 -> 1077.3067 | O8: =Inputs!$B$7*Income!O8/Income!O5/Inputs!$B$27 -> 1055.7606 | ... Q8: =Inputs!$B$7*Income!Q8/Income!Q5/Inputs!$B$27 -> 1013.9524
A9: Operating current assets / annualized revenue | H9: =Inputs!$B$7/Inputs!$B$27 -> 0.17422666 | I9: =Inputs!$B$7/Inputs!$B$27 -> 0.17422666 | J9: =Inputs!$B$7/Inputs!$B$27 -> 0.17422666 | K9: =Inputs!$B$7/Inputs!$B$27 -> 0.17422666 | L9: =Inputs!$B$7/Inputs!$B$27 -> 0.17422666 | M9: =Inputs!$B$7/Inputs!$B$27 -> 0.17422666 | N9: =Inputs!$B$7/Inputs!$B$27 -> 0.17422666 | O9: =Inputs!$B$7/Inputs!$B$27 -> 0.17422666 | ... Q9: =Inputs!$B$7/Inputs!$B$27 -> 0.17422666
A10: vendor_receivables | G10: =Inputs!$B$8 -> 0 | H10: =Inputs!$B$8*Income!H8/Income!H5/Inputs!$B$27 -> 0 | I10: =Inputs!$B$8*Income!I8/Income!I5/Inputs!$B$27 -> 0 | J10: =Inputs!$B$8*Income!J8/Income!J5/Inputs!$B$27 -> 0 | K10: =Inputs!$B$8*Income!K8/Income!K5/Inputs!$B$27 -> 0 | L10: =Inputs!$B$8*Income!L8/Income!L5/Inputs!$B$27 -> 0 | M10: =Inputs!$B$8*Income!M8/Income!M5/Inputs!$B$27 -> 0 | N10: =Inputs!$B$8*Income!N8/Income!N5/Inputs!$B$27 -> 0 | O10: =Inputs!$B$8*Income!O8/Income!O5/Inputs!$B$27 -> 0 | ... Q10: =Inputs!$B$8*Income!Q8/Income!Q5/Inputs!$B$27 -> 0
A12: Inventory | G12: =Inputs!$B$9 -> 0 | H12: =Inputs!$B$9*Income!H26/Income!H5/Inputs!$B$39 -> 0 | I12: =Inputs!$B$9*Income!I26/Income!I5/Inputs!$B$39 -> 0 | J12: =Inputs!$B$9*Income!J26/Income!J5/Inputs!$B$39 -> 0 | K12: =Inputs!$B$9*Income!K26/Income!K5/Inputs!$B$39 -> 0 | L12: =Inputs!$B$9*Income!L26/Income!L5/Inputs!$B$39 -> 0 | M12: =Inputs!$B$9*Income!M26/Income!M5/Inputs!$B$39 -> 0 | N12: =Inputs!$B$9*Income!N26/Income!N5/Inputs!$B$39 -> 0 | O12: =Inputs!$B$9*Income!O26/Income!O5/Inputs!$B$39 -> 0 | ... Q12: =Inputs!$B$9*Income!Q26/Income!Q5/Inputs!$B$39 -> 0
A13: Inventory / operating expenses | H13: =Inputs!$B$9/Inputs!$B$39 -> 0 | I13: =Inputs!$B$9/Inputs!$B$39 -> 0 | J13: =Inputs!$B$9/Inputs!$B$39 -> 0 | K13: =Inputs!$B$9/Inputs!$B$39 -> 0 | L13: =Inputs!$B$9/Inputs!$B$39 -> 0 | M13: =Inputs!$B$9/Inputs!$B$39 -> 0 | N13: =Inputs!$B$9/Inputs!$B$39 -> 0 | O13: =Inputs!$B$9/Inputs!$B$39 -> 0 | ... Q13: =Inputs!$B$9/Inputs!$B$39 -> 0
A14: Other current operating assets excluding disclosed intangibles | G14: =Inputs!$B$10 -> 0 | H14: =(Inputs!$B$10-Inputs!$B$13)*Income!H8/Income!H5/Inputs!$B$27 -> 0 | I14: =(Inputs!$B$10-Inputs!$B$13)*Income!I8/Income!I5/Inputs!$B$27 -> 0 | J14: =(Inputs!$B$10-Inputs!$B$13)*Income!J8/Income!J5/Inputs!$B$27 -> 0 | K14: =(Inputs!$B$10-Inputs!$B$13)*Income!K8/Income!K5/Inputs!$B$27 -> 0 | L14: =(Inputs!$B$10-Inputs!$B$13)*Income!L8/Income!L5/Inputs!$B$27 -> 0 | M14: =(Inputs!$B$10-Inputs!$B$13)*Income!M8/Income!M5/Inputs!$B$27 -> 0 | N14: =(Inputs!$B$10-Inputs!$B$13)*Income!N8/Income!N5/Inputs!$B$27 -> 0 | O14: =(Inputs!$B$10-Inputs!$B$13)*Income!O8/Income!O5/Inputs!$B$27 -> 0 | ... Q14: =(Inputs!$B$10-Inputs!$B$13)*Income!Q8/Income!Q5/Inputs!$B$27 -> 0
A18: Operating current liabilities | B18: =IF(ISNUMBER(History!B44),History!B44,"") -> 1290 | C18: =IF(ISNUMBER(History!C44),History!C44,"") -> 1379 | D18: =IF(ISNUMBER(History!D44),History!D44,"") -> 1289 | E18: =IF(ISNUMBER(History!E44),History!E44,"") -> 1231 | F18: =IF(ISNUMBER(History!F44),History!F44,"") -> 1311 | G18: =Inputs!$B$15 -> 1459 | H18: =Inputs!$B$15*Income!H26/Income!H5/Inputs!$B$39 -> 1412.6955 | I18: =Inputs!$B$15*Income!I26/Income!I5/Inputs!$B$39 -> 1384.4416 | J18: =Inputs!$B$15*Income!J26/Income!J5/Inputs!$B$39 -> 1356.7527 | K18: =Inputs!$B$15*Income!K26/Income!K5/Inputs!$B$39 -> 1329.6177 | L18: =Inputs!$B$15*Income!L26/Income!L5/Inputs!$B$39 -> 1303.0253 | M18: =Inputs!$B$15*Income!M26/Income!M5/Inputs!$B$39 -> 1276.9648 | N18: =Inputs!$B$15*Income!N26/Income!N5/Inputs!$B$39 -> 1251.4255 | O18: =Inputs!$B$15*Income!O26/Income!O5/Inputs!$B$39 -> 1226.397 | ... Q18: =Inputs!$B$15*Income!Q26/Income!Q5/Inputs!$B$39 -> 1177.8317
